try 
    a = test()
catch exception  
    % Handle the error here 
    disp(['Error occured:'exception.message]);
end 